<?xml version="1.0"?><robot name="pepe">
	<link name="0">
		<visual>
			<geometry>
				<cylinder length="0.5230673599617152" radius="0.07836652606024419"/>
			</geometry>
		</visual>
		<collision>
			<geometry>
				<cylinder length="0.5230673599617152" radius="0.07836652606024419"/>
			</geometry>
		</collision>
		<inertial>
			<mass value="0.010091801124406666"/>
			<inertia ixx="0.03" ixy="0" ixz="0" iyx="0" iyy="0.03" izz="0.03"/>
		</inertial>
	</link>
	<link name="11">
		<visual>
			<geometry>
				<cylinder length="0.8669926428735232" radius="0.08710938339079877"/>
			</geometry>
		</visual>
		<collision>
			<geometry>
				<cylinder length="0.8669926428735232" radius="0.08710938339079877"/>
			</geometry>
		</collision>
		<inertial>
			<mass value="0.02066784348313888"/>
			<inertia ixx="0.03" ixy="0" ixz="0" iyx="0" iyy="0.03" izz="0.03"/>
		</inertial>
	</link>
	<link name="32">
		<visual>
			<geometry>
				<cylinder length="0.5193488942877491" radius="0.9999"/>
			</geometry>
		</visual>
		<collision>
			<geometry>
				<cylinder length="0.5193488942877491" radius="0.9999"/>
			</geometry>
		</collision>
		<inertial>
			<mass value="1.6312563707260126"/>
			<inertia ixx="0.03" ixy="0" ixz="0" iyx="0" iyy="0.03" izz="0.03"/>
		</inertial>
	</link>
	<link name="23">
		<visual>
			<geometry>
				<cylinder length="0.7193488942877491" radius="0.9999"/>
			</geometry>
		</visual>
		<collision>
			<geometry>
				<cylinder length="0.7193488942877491" radius="0.9999"/>
			</geometry>
		</collision>
		<inertial>
			<mass value="2.2594492440210128"/>
			<inertia ixx="0.03" ixy="0" ixz="0" iyx="0" iyy="0.03" izz="0.03"/>
		</inertial>
	</link>
	<link name="44">
		<visual>
			<geometry>
				<cylinder length="0.31429930265885975" radius="0.6235049746617803"/>
			</geometry>
		</visual>
		<collision>
			<geometry>
				<cylinder length="0.31429930265885975" radius="0.6235049746617803"/>
			</geometry>
		</collision>
		<inertial>
			<mass value="0.38386024474465524"/>
			<inertia ixx="0.03" ixy="0" ixz="0" iyx="0" iyy="0.03" izz="0.03"/>
		</inertial>
	</link>
	<joint name="11_to_0" type="revolute">
		<parent link="0"/>
		<child link="11"/>
		<axis xyz="0 1 0"/>
		<limit effort="1" lower="3.1415" upper="-3.1415" velocity="1"/>
		<origin rpy="12.007440504779 2.343720709458729 0.757835571468532" xyz="0.8458982153510861 0.8495428260868736 0.2733804451619263"/>
	</joint>
	<joint name="32_to_11" type="revolute">
		<parent link="11"/>
		<child link="32"/>
		<axis xyz="0 0 1"/>
		<limit effort="1" lower="3.1415" upper="-3.1415" velocity="1"/>
		<origin rpy="5.107475086281181 6.282556988648868 6.282556988648868" xyz="0.9999 0.9999 0.3069430828837445"/>
	</joint>
	<joint name="23_to_0" type="revolute">
		<parent link="0"/>
		<child link="23"/>
		<axis xyz="0 0 1"/>
		<limit effort="1" lower="3.1415" upper="-3.1415" velocity="1"/>
		<origin rpy="9.546168221575648 6.282556988648868 6.282556988648868" xyz="0.9999 0.9999 0.20694308288374447"/>
	</joint>
	<joint name="44_to_0" type="revolute">
		<parent link="0"/>
		<child link="44"/>
		<axis xyz="0 1 0"/>
		<limit effort="1" lower="3.1415" upper="-3.1415" velocity="1"/>
		<origin rpy="8.280162887455393 1.5492331212387762 2.5357965924058323" xyz="0.528868182730234 0.9829652923630362 0.03029427048696387"/>
	</joint>
</robot>
