<?xml version="1.0"?><robot name="pepe">
	<link name="0">
		<visual>
			<geometry>
				<cylinder length="0.9017167583866756" radius="0.187704050513977"/>
			</geometry>
		</visual>
		<collision>
			<geometry>
				<cylinder length="0.9017167583866756" radius="0.187704050513977"/>
			</geometry>
		</collision>
		<inertial>
			<mass value="0.0998084480672481"/>
			<inertia ixx="0.03" ixy="0" ixz="0" iyx="0" iyy="0.03" izz="0.03"/>
		</inertial>
	</link>
	<link name="11">
		<visual>
			<geometry>
				<cylinder length="1.2502201745087476" radius="0.5854240211037078"/>
			</geometry>
		</visual>
		<collision>
			<geometry>
				<cylinder length="1.2502201745087476" radius="0.5854240211037078"/>
			</geometry>
		</collision>
		<inertial>
			<mass value="1.346100396798833"/>
			<inertia ixx="0.03" ixy="0" ixz="0" iyx="0" iyy="0.03" izz="0.03"/>
		</inertial>
	</link>
	<link name="22">
		<visual>
			<geometry>
				<cylinder length="1.0502201745087476" radius="0.7854240211037078"/>
			</geometry>
		</visual>
		<collision>
			<geometry>
				<cylinder length="1.0502201745087476" radius="0.7854240211037078"/>
			</geometry>
		</collision>
		<inertial>
			<mass value="2.0353475947281026"/>
			<inertia ixx="0.03" ixy="0" ixz="0" iyx="0" iyy="0.03" izz="0.03"/>
		</inertial>
	</link>
	<link name="23">
		<visual>
			<geometry>
				<cylinder length="1.0502201745087476" radius="0.7854240211037078"/>
			</geometry>
		</visual>
		<collision>
			<geometry>
				<cylinder length="1.0502201745087476" radius="0.7854240211037078"/>
			</geometry>
		</collision>
		<inertial>
			<mass value="2.0353475947281026"/>
			<inertia ixx="0.03" ixy="0" ixz="0" iyx="0" iyy="0.03" izz="0.03"/>
		</inertial>
	</link>
	<link name="24">
		<visual>
			<geometry>
				<cylinder length="1.0502201745087476" radius="0.7854240211037078"/>
			</geometry>
		</visual>
		<collision>
			<geometry>
				<cylinder length="1.0502201745087476" radius="0.7854240211037078"/>
			</geometry>
		</collision>
		<inertial>
			<mass value="2.0353475947281026"/>
			<inertia ixx="0.03" ixy="0" ixz="0" iyx="0" iyy="0.03" izz="0.03"/>
		</inertial>
	</link>
	<link name="35">
		<visual>
			<geometry>
				<cylinder length="1.259321371083875" radius="0.9553800966042814"/>
			</geometry>
		</visual>
		<collision>
			<geometry>
				<cylinder length="1.259321371083875" radius="0.9553800966042814"/>
			</geometry>
		</collision>
		<inertial>
			<mass value="3.6110942609911323"/>
			<inertia ixx="0.03" ixy="0" ixz="0" iyx="0" iyy="0.03" izz="0.03"/>
		</inertial>
	</link>
	<link name="36">
		<visual>
			<geometry>
				<cylinder length="1.259321371083875" radius="0.9553800966042814"/>
			</geometry>
		</visual>
		<collision>
			<geometry>
				<cylinder length="1.259321371083875" radius="0.9553800966042814"/>
			</geometry>
		</collision>
		<inertial>
			<mass value="3.6110942609911323"/>
			<inertia ixx="0.03" ixy="0" ixz="0" iyx="0" iyy="0.03" izz="0.03"/>
		</inertial>
	</link>
	<link name="17">
		<visual>
			<geometry>
				<cylinder length="1.2502201745087476" radius="0.5854240211037078"/>
			</geometry>
		</visual>
		<collision>
			<geometry>
				<cylinder length="1.2502201745087476" radius="0.5854240211037078"/>
			</geometry>
		</collision>
		<inertial>
			<mass value="1.346100396798833"/>
			<inertia ixx="0.03" ixy="0" ixz="0" iyx="0" iyy="0.03" izz="0.03"/>
		</inertial>
	</link>
	<link name="28">
		<visual>
			<geometry>
				<cylinder length="1.0502201745087476" radius="0.7854240211037078"/>
			</geometry>
		</visual>
		<collision>
			<geometry>
				<cylinder length="1.0502201745087476" radius="0.7854240211037078"/>
			</geometry>
		</collision>
		<inertial>
			<mass value="2.0353475947281026"/>
			<inertia ixx="0.03" ixy="0" ixz="0" iyx="0" iyy="0.03" izz="0.03"/>
		</inertial>
	</link>
	<link name="29">
		<visual>
			<geometry>
				<cylinder length="1.0502201745087476" radius="0.7854240211037078"/>
			</geometry>
		</visual>
		<collision>
			<geometry>
				<cylinder length="1.0502201745087476" radius="0.7854240211037078"/>
			</geometry>
		</collision>
		<inertial>
			<mass value="2.0353475947281026"/>
			<inertia ixx="0.03" ixy="0" ixz="0" iyx="0" iyy="0.03" izz="0.03"/>
		</inertial>
	</link>
	<link name="210">
		<visual>
			<geometry>
				<cylinder length="1.0502201745087476" radius="0.7854240211037078"/>
			</geometry>
		</visual>
		<collision>
			<geometry>
				<cylinder length="1.0502201745087476" radius="0.7854240211037078"/>
			</geometry>
		</collision>
		<inertial>
			<mass value="2.0353475947281026"/>
			<inertia ixx="0.03" ixy="0" ixz="0" iyx="0" iyy="0.03" izz="0.03"/>
		</inertial>
	</link>
	<link name="311">
		<visual>
			<geometry>
				<cylinder length="1.259321371083875" radius="0.9553800966042814"/>
			</geometry>
		</visual>
		<collision>
			<geometry>
				<cylinder length="1.259321371083875" radius="0.9553800966042814"/>
			</geometry>
		</collision>
		<inertial>
			<mass value="3.6110942609911323"/>
			<inertia ixx="0.03" ixy="0" ixz="0" iyx="0" iyy="0.03" izz="0.03"/>
		</inertial>
	</link>
	<link name="312">
		<visual>
			<geometry>
				<cylinder length="1.259321371083875" radius="0.9553800966042814"/>
			</geometry>
		</visual>
		<collision>
			<geometry>
				<cylinder length="1.259321371083875" radius="0.9553800966042814"/>
			</geometry>
		</collision>
		<inertial>
			<mass value="3.6110942609911323"/>
			<inertia ixx="0.03" ixy="0" ixz="0" iyx="0" iyy="0.03" izz="0.03"/>
		</inertial>
	</link>
	<link name="113">
		<visual>
			<geometry>
				<cylinder length="1.2502201745087476" radius="0.5854240211037078"/>
			</geometry>
		</visual>
		<collision>
			<geometry>
				<cylinder length="1.2502201745087476" radius="0.5854240211037078"/>
			</geometry>
		</collision>
		<inertial>
			<mass value="1.346100396798833"/>
			<inertia ixx="0.03" ixy="0" ixz="0" iyx="0" iyy="0.03" izz="0.03"/>
		</inertial>
	</link>
	<link name="214">
		<visual>
			<geometry>
				<cylinder length="1.0502201745087476" radius="0.7854240211037078"/>
			</geometry>
		</visual>
		<collision>
			<geometry>
				<cylinder length="1.0502201745087476" radius="0.7854240211037078"/>
			</geometry>
		</collision>
		<inertial>
			<mass value="2.0353475947281026"/>
			<inertia ixx="0.03" ixy="0" ixz="0" iyx="0" iyy="0.03" izz="0.03"/>
		</inertial>
	</link>
	<link name="215">
		<visual>
			<geometry>
				<cylinder length="1.0502201745087476" radius="0.7854240211037078"/>
			</geometry>
		</visual>
		<collision>
			<geometry>
				<cylinder length="1.0502201745087476" radius="0.7854240211037078"/>
			</geometry>
		</collision>
		<inertial>
			<mass value="2.0353475947281026"/>
			<inertia ixx="0.03" ixy="0" ixz="0" iyx="0" iyy="0.03" izz="0.03"/>
		</inertial>
	</link>
	<link name="216">
		<visual>
			<geometry>
				<cylinder length="1.0502201745087476" radius="0.7854240211037078"/>
			</geometry>
		</visual>
		<collision>
			<geometry>
				<cylinder length="1.0502201745087476" radius="0.7854240211037078"/>
			</geometry>
		</collision>
		<inertial>
			<mass value="2.0353475947281026"/>
			<inertia ixx="0.03" ixy="0" ixz="0" iyx="0" iyy="0.03" izz="0.03"/>
		</inertial>
	</link>
	<link name="317">
		<visual>
			<geometry>
				<cylinder length="1.259321371083875" radius="0.9553800966042814"/>
			</geometry>
		</visual>
		<collision>
			<geometry>
				<cylinder length="1.259321371083875" radius="0.9553800966042814"/>
			</geometry>
		</collision>
		<inertial>
			<mass value="3.6110942609911323"/>
			<inertia ixx="0.03" ixy="0" ixz="0" iyx="0" iyy="0.03" izz="0.03"/>
		</inertial>
	</link>
	<link name="318">
		<visual>
			<geometry>
				<cylinder length="1.259321371083875" radius="0.9553800966042814"/>
			</geometry>
		</visual>
		<collision>
			<geometry>
				<cylinder length="1.259321371083875" radius="0.9553800966042814"/>
			</geometry>
		</collision>
		<inertial>
			<mass value="3.6110942609911323"/>
			<inertia ixx="0.03" ixy="0" ixz="0" iyx="0" iyy="0.03" izz="0.03"/>
		</inertial>
	</link>
	<joint name="11_to_0" type="revolute">
		<parent link="0"/>
		<child link="11"/>
		<axis xyz="0 1 0"/>
		<limit effort="1" lower="3.1415" upper="-3.1415" velocity="1"/>
		<origin rpy="5.441095379786588 6.282556988648868 5.687411397648708" xyz="0.9906611605527152 0.7726048838496601 0.9999"/>
	</joint>
	<joint name="22_to_11" type="revolute">
		<parent link="11"/>
		<child link="22"/>
		<axis xyz="0 0 1"/>
		<limit effort="1" lower="3.1415" upper="-3.1415" velocity="1"/>
		<origin rpy="5.441095379786588 6.282556988648868 5.687411397648708" xyz="0.9999 0.6726048838496601 0.9999"/>
	</joint>
	<joint name="23_to_11" type="revolute">
		<parent link="11"/>
		<child link="23"/>
		<axis xyz="0 0 1"/>
		<limit effort="1" lower="3.1415" upper="-3.1415" velocity="1"/>
		<origin rpy="8.161643069679881 6.282556988648868 5.687411397648708" xyz="0.9999 0.6726048838496601 0.9999"/>
	</joint>
	<joint name="24_to_11" type="revolute">
		<parent link="11"/>
		<child link="24"/>
		<axis xyz="0 0 1"/>
		<limit effort="1" lower="3.1415" upper="-3.1415" velocity="1"/>
		<origin rpy="10.882190759573175 6.282556988648868 5.687411397648708" xyz="0.9999 0.6726048838496601 0.9999"/>
	</joint>
	<joint name="35_to_11" type="revolute">
		<parent link="11"/>
		<child link="35"/>
		<axis xyz="0 1 0"/>
		<limit effort="1" lower="3.1415" upper="-3.1415" velocity="1"/>
		<origin rpy="21.695585067437094 1.2111774207471717 5.660594498188821" xyz="0.8348194956268116 0.8576161000501391 0.4196896159249177"/>
	</joint>
	<joint name="36_to_11" type="revolute">
		<parent link="11"/>
		<child link="36"/>
		<axis xyz="0 1 0"/>
		<limit effort="1" lower="3.1415" upper="-3.1415" velocity="1"/>
		<origin rpy="26.034702080924514 1.2111774207471717 5.660594498188821" xyz="0.8348194956268116 0.8576161000501391 0.4196896159249177"/>
	</joint>
	<joint name="17_to_0" type="revolute">
		<parent link="0"/>
		<child link="17"/>
		<axis xyz="0 1 0"/>
		<limit effort="1" lower="3.1415" upper="-3.1415" velocity="1"/>
		<origin rpy="8.161643069679881 6.282556988648868 5.687411397648708" xyz="0.9906611605527152 0.7726048838496601 0.9999"/>
	</joint>
	<joint name="28_to_17" type="revolute">
		<parent link="17"/>
		<child link="28"/>
		<axis xyz="0 0 1"/>
		<limit effort="1" lower="3.1415" upper="-3.1415" velocity="1"/>
		<origin rpy="5.441095379786588 6.282556988648868 5.687411397648708" xyz="0.9999 0.6726048838496601 0.9999"/>
	</joint>
	<joint name="29_to_17" type="revolute">
		<parent link="17"/>
		<child link="29"/>
		<axis xyz="0 0 1"/>
		<limit effort="1" lower="3.1415" upper="-3.1415" velocity="1"/>
		<origin rpy="8.161643069679881 6.282556988648868 5.687411397648708" xyz="0.9999 0.6726048838496601 0.9999"/>
	</joint>
	<joint name="210_to_17" type="revolute">
		<parent link="17"/>
		<child link="210"/>
		<axis xyz="0 0 1"/>
		<limit effort="1" lower="3.1415" upper="-3.1415" velocity="1"/>
		<origin rpy="10.882190759573175 6.282556988648868 5.687411397648708" xyz="0.9999 0.6726048838496601 0.9999"/>
	</joint>
	<joint name="311_to_17" type="revolute">
		<parent link="17"/>
		<child link="311"/>
		<axis xyz="0 1 0"/>
		<limit effort="1" lower="3.1415" upper="-3.1415" velocity="1"/>
		<origin rpy="21.695585067437094 1.2111774207471717 5.660594498188821" xyz="0.8348194956268116 0.8576161000501391 0.4196896159249177"/>
	</joint>
	<joint name="312_to_17" type="revolute">
		<parent link="17"/>
		<child link="312"/>
		<axis xyz="0 1 0"/>
		<limit effort="1" lower="3.1415" upper="-3.1415" velocity="1"/>
		<origin rpy="26.034702080924514 1.2111774207471717 5.660594498188821" xyz="0.8348194956268116 0.8576161000501391 0.4196896159249177"/>
	</joint>
	<joint name="113_to_0" type="revolute">
		<parent link="0"/>
		<child link="113"/>
		<axis xyz="0 1 0"/>
		<limit effort="1" lower="3.1415" upper="-3.1415" velocity="1"/>
		<origin rpy="10.882190759573175 6.282556988648868 5.687411397648708" xyz="0.9906611605527152 0.7726048838496601 0.9999"/>
	</joint>
	<joint name="214_to_113" type="revolute">
		<parent link="113"/>
		<child link="214"/>
		<axis xyz="0 0 1"/>
		<limit effort="1" lower="3.1415" upper="-3.1415" velocity="1"/>
		<origin rpy="5.441095379786588 6.282556988648868 5.687411397648708" xyz="0.9999 0.6726048838496601 0.9999"/>
	</joint>
	<joint name="215_to_113" type="revolute">
		<parent link="113"/>
		<child link="215"/>
		<axis xyz="0 0 1"/>
		<limit effort="1" lower="3.1415" upper="-3.1415" velocity="1"/>
		<origin rpy="8.161643069679881 6.282556988648868 5.687411397648708" xyz="0.9999 0.6726048838496601 0.9999"/>
	</joint>
	<joint name="216_to_113" type="revolute">
		<parent link="113"/>
		<child link="216"/>
		<axis xyz="0 0 1"/>
		<limit effort="1" lower="3.1415" upper="-3.1415" velocity="1"/>
		<origin rpy="10.882190759573175 6.282556988648868 5.687411397648708" xyz="0.9999 0.6726048838496601 0.9999"/>
	</joint>
	<joint name="317_to_113" type="revolute">
		<parent link="113"/>
		<child link="317"/>
		<axis xyz="0 1 0"/>
		<limit effort="1" lower="3.1415" upper="-3.1415" velocity="1"/>
		<origin rpy="21.695585067437094 1.2111774207471717 5.660594498188821" xyz="0.8348194956268116 0.8576161000501391 0.4196896159249177"/>
	</joint>
	<joint name="318_to_113" type="revolute">
		<parent link="113"/>
		<child link="318"/>
		<axis xyz="0 1 0"/>
		<limit effort="1" lower="3.1415" upper="-3.1415" velocity="1"/>
		<origin rpy="26.034702080924514 1.2111774207471717 5.660594498188821" xyz="0.8348194956268116 0.8576161000501391 0.4196896159249177"/>
	</joint>
</robot>
