<?xml version="1.0"?><robot name="pepe">
	<link name="0">
		<visual>
			<geometry>
				<cylinder length="1.9998" radius="0.8405738840557292"/>
			</geometry>
		</visual>
		<collision>
			<geometry>
				<cylinder length="1.9998" radius="0.8405738840557292"/>
			</geometry>
		</collision>
		<inertial>
			<mass value="4.439031451905032"/>
			<inertia ixx="0.03" ixy="0" ixz="0" iyx="0" iyy="0.03" izz="0.03"/>
		</inertial>
	</link>
	<link name="11">
		<visual>
			<geometry>
				<cylinder length="1.3094172599115697" radius="0.6426231177273677"/>
			</geometry>
		</visual>
		<collision>
			<geometry>
				<cylinder length="1.3094172599115697" radius="0.6426231177273677"/>
			</geometry>
		</collision>
		<inertial>
			<mass value="1.698793628792556"/>
			<inertia ixx="0.03" ixy="0" ixz="0" iyx="0" iyy="0.03" izz="0.03"/>
		</inertial>
	</link>
	<link name="22">
		<visual>
			<geometry>
				<cylinder length="0.4304539372306577" radius="0.17302302438452677"/>
			</geometry>
		</visual>
		<collision>
			<geometry>
				<cylinder length="0.4304539372306577" radius="0.17302302438452677"/>
			</geometry>
		</collision>
		<inertial>
			<mass value="0.040484087548324665"/>
			<inertia ixx="0.03" ixy="0" ixz="0" iyx="0" iyy="0.03" izz="0.03"/>
		</inertial>
	</link>
	<joint name="11_to_0" type="revolute">
		<parent link="0"/>
		<child link="11"/>
		<axis xyz="1 0 0"/>
		<limit effort="1" lower="3.1415" upper="-3.1415" velocity="1"/>
		<origin rpy="9.060543452151135 0.8531702846742658 5.922594166840074" xyz="0.4002012118600625 0.047759829224858 0.23077846439025285"/>
	</joint>
	<joint name="22_to_0" type="revolute">
		<parent link="0"/>
		<child link="22"/>
		<axis xyz="1 0 0"/>
		<limit effort="1" lower="3.1415" upper="-3.1415" velocity="1"/>
		<origin rpy="13.268673684520797 5.511828184997574 4.905448125934964" xyz="0.9091717750826634 0.12762664099450394 0.20498907537559674"/>
	</joint>
</robot>
