<?xml version="1.0"?><robot name="pepe">
	<link name="0">
		<visual>
			<geometry>
				<cylinder length="1.3027125246961713" radius="0.7829529922033459"/>
			</geometry>
		</visual>
		<collision>
			<geometry>
				<cylinder length="1.3027125246961713" radius="0.7829529922033459"/>
			</geometry>
		</collision>
		<inertial>
			<mass value="2.508821932468066"/>
			<inertia ixx="0.03" ixy="0" ixz="0" iyx="0" iyy="0.03" izz="0.03"/>
		</inertial>
	</link>
	<link name="11">
		<visual>
			<geometry>
				<cylinder length="1.8843324128801913" radius="0.19056588350260817"/>
			</geometry>
		</visual>
		<collision>
			<geometry>
				<cylinder length="1.8843324128801913" radius="0.19056588350260817"/>
			</geometry>
		</collision>
		<inertial>
			<mass value="0.21497982086557357"/>
			<inertia ixx="0.03" ixy="0" ixz="0" iyx="0" iyy="0.03" izz="0.03"/>
		</inertial>
	</link>
	<link name="22">
		<visual>
			<geometry>
				<cylinder length="0.4618823797775875" radius="0.05779289334218429"/>
			</geometry>
		</visual>
		<collision>
			<geometry>
				<cylinder length="0.4618823797775875" radius="0.05779289334218429"/>
			</geometry>
		</collision>
		<inertial>
			<mass value="0.004846521487007137"/>
			<inertia ixx="0.03" ixy="0" ixz="0" iyx="0" iyy="0.03" izz="0.03"/>
		</inertial>
	</link>
	<link name="23">
		<visual>
			<geometry>
				<cylinder length="0.4618823797775875" radius="0.05779289334218429"/>
			</geometry>
		</visual>
		<collision>
			<geometry>
				<cylinder length="0.4618823797775875" radius="0.05779289334218429"/>
			</geometry>
		</collision>
		<inertial>
			<mass value="0.004846521487007137"/>
			<inertia ixx="0.03" ixy="0" ixz="0" iyx="0" iyy="0.03" izz="0.03"/>
		</inertial>
	</link>
	<link name="24">
		<visual>
			<geometry>
				<cylinder length="0.4618823797775875" radius="0.05779289334218429"/>
			</geometry>
		</visual>
		<collision>
			<geometry>
				<cylinder length="0.4618823797775875" radius="0.05779289334218429"/>
			</geometry>
		</collision>
		<inertial>
			<mass value="0.004846521487007137"/>
			<inertia ixx="0.03" ixy="0" ixz="0" iyx="0" iyy="0.03" izz="0.03"/>
		</inertial>
	</link>
	<joint name="11_to_0" type="revolute">
		<parent link="0"/>
		<child link="11"/>
		<axis xyz="0 0 1"/>
		<limit effort="1" lower="3.1415" upper="-3.1415" velocity="1"/>
		<origin rpy="12.14274553194132 6.046821119140343 5.4519879205980954" xyz="0.4215110883640615 0.2188065997501728 0.9398203673718867"/>
	</joint>
	<joint name="22_to_11" type="revolute">
		<parent link="11"/>
		<child link="22"/>
		<axis xyz="1 0 0"/>
		<limit effort="1" lower="3.1415" upper="-3.1415" velocity="1"/>
		<origin rpy="11.854298137734773 5.175247813080558 4.195008801091541" xyz="0.36952773696045593 0.10836644126601783 0.5477438343449981"/>
	</joint>
	<joint name="23_to_11" type="revolute">
		<parent link="11"/>
		<child link="23"/>
		<axis xyz="1 0 0"/>
		<limit effort="1" lower="3.1415" upper="-3.1415" velocity="1"/>
		<origin rpy="17.78144720660216 5.175247813080558 4.195008801091541" xyz="0.36952773696045593 0.10836644126601783 0.5477438343449981"/>
	</joint>
	<joint name="24_to_11" type="revolute">
		<parent link="11"/>
		<child link="24"/>
		<axis xyz="1 0 0"/>
		<limit effort="1" lower="3.1415" upper="-3.1415" velocity="1"/>
		<origin rpy="23.708596275469546 5.175247813080558 4.195008801091541" xyz="0.36952773696045593 0.10836644126601783 0.5477438343449981"/>
	</joint>
</robot>
