<?xml version="1.0"?><robot name="pepe">
	<link name="0">
		<visual>
			<geometry>
				<cylinder length="0.7193488942877491" radius="0.9999"/>
			</geometry>
		</visual>
		<collision>
			<geometry>
				<cylinder length="0.7193488942877491" radius="0.9999"/>
			</geometry>
		</collision>
		<inertial>
			<mass value="2.2594492440210128"/>
			<inertia ixx="0.03" ixy="0" ixz="0" iyx="0" iyy="0.03" izz="0.03"/>
		</inertial>
	</link>
	<link name="11">
		<visual>
			<geometry>
				<cylinder length="0.6193488942877491" radius="0.9999"/>
			</geometry>
		</visual>
		<collision>
			<geometry>
				<cylinder length="0.6193488942877491" radius="0.9999"/>
			</geometry>
		</collision>
		<inertial>
			<mass value="1.9453528073735127"/>
			<inertia ixx="0.03" ixy="0" ixz="0" iyx="0" iyy="0.03" izz="0.03"/>
		</inertial>
	</link>
	<link name="32">
		<visual>
			<geometry>
				<cylinder length="0.7193488942877491" radius="0.9999"/>
			</geometry>
		</visual>
		<collision>
			<geometry>
				<cylinder length="0.7193488942877491" radius="0.9999"/>
			</geometry>
		</collision>
		<inertial>
			<mass value="2.2594492440210128"/>
			<inertia ixx="0.03" ixy="0" ixz="0" iyx="0" iyy="0.03" izz="0.03"/>
		</inertial>
	</link>
	<link name="23">
		<visual>
			<geometry>
				<cylinder length="0.8669926428735232" radius="0.08710938339079877"/>
			</geometry>
		</visual>
		<collision>
			<geometry>
				<cylinder length="0.8669926428735232" radius="0.08710938339079877"/>
			</geometry>
		</collision>
		<inertial>
			<mass value="0.02066784348313888"/>
			<inertia ixx="0.03" ixy="0" ixz="0" iyx="0" iyy="0.03" izz="0.03"/>
		</inertial>
	</link>
	<link name="44">
		<visual>
			<geometry>
				<cylinder length="0.12443131712763478" radius="0.18573756694812382"/>
			</geometry>
		</visual>
		<collision>
			<geometry>
				<cylinder length="0.12443131712763478" radius="0.18573756694812382"/>
			</geometry>
		</collision>
		<inertial>
			<mass value="0.013485873308373975"/>
			<inertia ixx="0.03" ixy="0" ixz="0" iyx="0" iyy="0.03" izz="0.03"/>
		</inertial>
	</link>
	<joint name="11_to_0" type="revolute">
		<parent link="0"/>
		<child link="11"/>
		<axis xyz="0 0 1"/>
		<limit effort="1" lower="3.1415" upper="-3.1415" velocity="1"/>
		<origin rpy="6.3641121477170985 6.282556988648868 6.282556988648868" xyz="0.9999 0.9999 0.3069430828837445"/>
	</joint>
	<joint name="32_to_11" type="revolute">
		<parent link="11"/>
		<child link="32"/>
		<axis xyz="0 0 1"/>
		<limit effort="1" lower="3.1415" upper="-3.1415" velocity="1"/>
		<origin rpy="5.107475086281181 6.282556988648868 6.282556988648868" xyz="0.9999 0.9999 0.5069430828837445"/>
	</joint>
	<joint name="23_to_0" type="revolute">
		<parent link="0"/>
		<child link="23"/>
		<axis xyz="0 1 0"/>
		<limit effort="1" lower="3.1415" upper="-3.1415" velocity="1"/>
		<origin rpy="16.126205165014625 1.7154021787407705 0.757835571468532" xyz="0.8458982153510861 0.8495428260868736 0.37338044516192626"/>
	</joint>
	<joint name="44_to_0" type="revolute">
		<parent link="0"/>
		<child link="44"/>
		<axis xyz="1 0 0"/>
		<limit effort="1" lower="3.1415" upper="-3.1415" velocity="1"/>
		<origin rpy="16.614113858757964 5.9545604583241145 2.686502467429438" xyz="0.8496395744908001 0.7047834527789605 0.7132043539178358"/>
	</joint>
</robot>
